<?xml version="1.0" ?>
<!-- =================================================================================== -->
<!-- |    This document was autogenerated by xacro from arm_description/urdf/arm.xacro | -->
<!-- |    EDITING THIS FILE BY HAND IS NOT RECOMMENDED                                 | -->
<!-- =================================================================================== -->
<robot name="arm">
  <material name="silver_default">
    <color rgba="0.700 0.700 0.700 1.000"/>
  </material>
  <material name="abs_white">
    <color rgba="0.9647058823529412 0.9647058823529412 0.9529411764705882 1.0"/>
  </material>
  <material name="steel_satin">
    <color rgba="0.6274509803921569 0.6274509803921569 0.6274509803921569 1.0"/>
  </material>
  <material name="acetal_resin_white">
    <color rgba="0.9725490196078431 0.9686274509803922 0.9294117647058824 1.0"/>
  </material>
  <transmission name="Slider 2_tran">
    <type>transmission_interface/SimpleTransmission</type>
    <joint name="Slider 2">
      <hardwareInterface>hardware_interface/EffortJointInterface</hardwareInterface>
    </joint>
    <actuator name="Slider 2_actr">
      <hardwareInterface>hardware_interface/EffortJointInterface</hardwareInterface>
      <mechanicalReduction>1</mechanicalReduction>
    </actuator>
  </transmission>
  <transmission name="Revolute 5_tran">
    <type>transmission_interface/SimpleTransmission</type>
    <joint name="Revolute 5">
      <hardwareInterface>hardware_interface/EffortJointInterface</hardwareInterface>
    </joint>
    <actuator name="Revolute 5_actr">
      <hardwareInterface>hardware_interface/EffortJointInterface</hardwareInterface>
      <mechanicalReduction>1</mechanicalReduction>
    </actuator>
  </transmission>
  <transmission name="Revolute 12_tran">
    <type>transmission_interface/SimpleTransmission</type>
    <joint name="Revolute 12">
      <hardwareInterface>hardware_interface/EffortJointInterface</hardwareInterface>
    </joint>
    <actuator name="Revolute 12_actr">
      <hardwareInterface>hardware_interface/EffortJointInterface</hardwareInterface>
      <mechanicalReduction>1</mechanicalReduction>
    </actuator>
  </transmission>
  <transmission name="Revolute 13_tran">
    <type>transmission_interface/SimpleTransmission</type>
    <joint name="Revolute 13">
      <hardwareInterface>hardware_interface/EffortJointInterface</hardwareInterface>
    </joint>
    <actuator name="Revolute 13_actr">
      <hardwareInterface>hardware_interface/EffortJointInterface</hardwareInterface>
      <mechanicalReduction>1</mechanicalReduction>
    </actuator>
  </transmission>
  <transmission name="Slider 18_tran">
    <type>transmission_interface/SimpleTransmission</type>
    <joint name="Slider 18">
      <hardwareInterface>hardware_interface/EffortJointInterface</hardwareInterface>
    </joint>
    <actuator name="Slider 18_actr">
      <hardwareInterface>hardware_interface/EffortJointInterface</hardwareInterface>
      <mechanicalReduction>1</mechanicalReduction>
    </actuator>
  </transmission>
  <transmission name="Slider 19_tran">
    <type>transmission_interface/SimpleTransmission</type>
    <joint name="Slider 19">
      <hardwareInterface>hardware_interface/EffortJointInterface</hardwareInterface>
    </joint>
    <actuator name="Slider 19_actr">
      <hardwareInterface>hardware_interface/EffortJointInterface</hardwareInterface>
      <mechanicalReduction>1</mechanicalReduction>
    </actuator>
  </transmission>
  <link name="base_link">
    <inertial>
      <origin rpy="0 0 0" xyz="-0.009999999999999943 -0.30000000000000016 -0.08999999999999994"/>
      <mass value="3.2806614531742855"/>
      <inertia ixx="0.330921" ixy="0.0" ixz="0.0" iyy="0.00057" iyz="0.0" izz="0.331249"/>
    </inertial>
    <visual>
      <origin rpy="0 0 0" xyz="0 0 0"/>
      <geometry>
        <mesh filename="../meshes/base_link.stl" scale="0.001 0.001 0.001"/>
      </geometry>
      <material name="steel_satin"/>
    </visual>
    <collision>
      <origin rpy="0 0 0" xyz="0 0 0"/>
      <geometry>
        <mesh filename="../meshes/base_link.stl" scale="0.001 0.001 0.001"/>
      </geometry>
    </collision>
  </link>
  <link name="glid_platta_1">
    <inertial>
      <origin rpy="0 0 0" xyz="-5.468439568776136e-05 -0.05383161524004917 0.0038176877551246158"/>
      <mass value="0.8546275738182918"/>
      <inertia ixx="0.002722" ixy="-6e-06" ixz="1e-06" iyy="0.000445" iyz="6e-06" izz="0.003156"/>
    </inertial>
    <visual>
      <origin rpy="0 0 0" xyz="0.01 0.0005 0.077"/>
      <geometry>
        <mesh filename="../meshes/glid_platta_1.stl" scale="0.001 0.001 0.001"/>
      </geometry>
      <material name="abs_white"/>
    </visual>
    <collision>
      <origin rpy="0 0 0" xyz="0.01 0.0005 0.077"/>
      <geometry>
        <mesh filename="../meshes/glid_platta_1.stl" scale="0.001 0.001 0.001"/>
      </geometry>
    </collision>
  </link>
  <link name="bas_1">
    <inertial>
      <origin rpy="0 0 0" xyz="0.04705931573620517 0.045268301136539645 0.0022661004887333247"/>
      <mass value="0.30456940392755205"/>
      <inertia ixx="0.000197" ixy="-5.5e-05" ixz="0.0" iyy="0.000386" iyz="-0.0" izz="0.000582"/>
    </inertial>
    <visual>
      <origin rpy="0 0 0" xyz="0.04 0.0955 0.061"/>
      <geometry>
        <mesh filename="../meshes/bas_1.stl" scale="0.001 0.001 0.001"/>
      </geometry>
      <material name="abs_white"/>
    </visual>
    <collision>
      <origin rpy="0 0 0" xyz="0.04 0.0955 0.061"/>
      <geometry>
        <mesh filename="../meshes/bas_1.stl" scale="0.001 0.001 0.001"/>
      </geometry>
    </collision>
  </link>
  <link name="gemensam_vagg_1">
    <inertial>
      <origin rpy="0 0 0" xyz="0.030946920895249638 0.0021147724207146537 0.021010163827367916"/>
      <mass value="0.14972234810656923"/>
      <inertia ixx="2.6e-05" ixy="4e-06" ixz="-2e-06" iyy="0.000104" iyz="-1e-06" izz="8.3e-05"/>
    </inertial>
    <visual>
      <origin rpy="0 0 0" xyz="0.025 0.006 0.0565"/>
      <geometry>
        <mesh filename="../meshes/gemensam_vagg_1.stl" scale="0.001 0.001 0.001"/>
      </geometry>
      <material name="abs_white"/>
    </visual>
    <collision>
      <origin rpy="0 0 0" xyz="0.025 0.006 0.0565"/>
      <geometry>
        <mesh filename="../meshes/gemensam_vagg_1.stl" scale="0.001 0.001 0.001"/>
      </geometry>
    </collision>
  </link>
  <link name="botten_snurr_1">
    <inertial>
      <origin rpy="0 0 0" xyz="0.0015732210889561407 -0.03123421175585632 -0.00431527689408236"/>
      <mass value="0.3353218247510541"/>
      <inertia ixx="0.000386" ixy="2e-06" ixz="6e-06" iyy="0.000177" iyz="-5e-06" izz="0.000373"/>
    </inertial>
    <visual>
      <origin rpy="0 0 0" xyz="0.0175 0.0083 0.016"/>
      <geometry>
        <mesh filename="../meshes/botten_snurr_1.stl" scale="0.001 0.001 0.001"/>
      </geometry>
      <material name="abs_white"/>
    </visual>
    <collision>
      <origin rpy="0 0 0" xyz="0.0175 0.0083 0.016"/>
      <geometry>
        <mesh filename="../meshes/botten_snurr_1.stl" scale="0.001 0.001 0.001"/>
      </geometry>
    </collision>
  </link>
  <link name="kortarm_kopia_Mirror__1">
    <inertial>
      <origin rpy="0 0 0" xyz="0.008999999999998776 -0.002527975348214296 0.12374230942748185"/>
      <mass value="0.14674833087457098"/>
      <inertia ixx="0.000901" ixy="0.0" ixz="-0.0" iyy="0.000919" iyz="-0.0" izz="1.9e-05"/>
    </inertial>
    <visual>
      <origin rpy="0 0 0" xyz="0.0265 0.0173 0.001"/>
      <geometry>
        <mesh filename="../meshes/kortarm_kopia_Mirror__1.stl" scale="0.001 0.001 0.001"/>
      </geometry>
      <material name="abs_white"/>
    </visual>
    <collision>
      <origin rpy="0 0 0" xyz="0.0265 0.0173 0.001"/>
      <geometry>
        <mesh filename="../meshes/kortarm_kopia_Mirror__1.stl" scale="0.001 0.001 0.001"/>
      </geometry>
    </collision>
  </link>
  <link name="kortarm_kopia_1">
    <inertial>
      <origin rpy="0 0 0" xyz="-0.008999999999983271 0.0025846658949611606 0.12043864331762873"/>
      <mass value="0.15923511176845098"/>
      <inertia ixx="0.000967" ixy="-0.0" ixz="0.0" iyy="0.000986" iyz="2e-06" izz="2e-05"/>
    </inertial>
    <visual>
      <origin rpy="0 0 0" xyz="0.0085 0.0673 0.001"/>
      <geometry>
        <mesh filename="../meshes/kortarm_kopia_1.stl" scale="0.001 0.001 0.001"/>
      </geometry>
      <material name="abs_white"/>
    </visual>
    <collision>
      <origin rpy="0 0 0" xyz="0.0085 0.0673 0.001"/>
      <geometry>
        <mesh filename="../meshes/kortarm_kopia_1.stl" scale="0.001 0.001 0.001"/>
      </geometry>
    </collision>
  </link>
  <link name="snurr_hallare_stepper_sida_1">
    <inertial>
      <origin rpy="0 0 0" xyz="-0.00752161763889087 -0.0010441466152069923 0.030069945529443327"/>
      <mass value="0.10064962572181504"/>
      <inertia ixx="3.3e-05" ixy="0.0" ixz="-0.0" iyy="4.6e-05" iyz="-0.0" izz="1.4e-05"/>
    </inertial>
    <visual>
      <origin rpy="0 0 0" xyz="0.01 0.08 0.0565"/>
      <geometry>
        <mesh filename="../meshes/snurr_hallare_stepper_sida_1.stl" scale="0.001 0.001 0.001"/>
      </geometry>
      <material name="acetal_resin_white"/>
    </visual>
    <collision>
      <origin rpy="0 0 0" xyz="0.01 0.08 0.0565"/>
      <geometry>
        <mesh filename="../meshes/snurr_hallare_stepper_sida_1.stl" scale="0.001 0.001 0.001"/>
      </geometry>
    </collision>
  </link>
  <link name="led_1">
    <inertial>
      <origin rpy="0 0 0" xyz="0.01030928189216322 0.011669647371074766 0.010617976474143143"/>
      <mass value="0.12568698050315202"/>
      <inertia ixx="7.4e-05" ixy="8e-06" ixz="-6e-06" iyy="3.2e-05" iyz="2.1e-05" izz="5.7e-05"/>
    </inertial>
    <visual>
      <origin rpy="0 0 0" xyz="0.025 0.0633 -0.244"/>
      <geometry>
        <mesh filename="../meshes/led_1.stl" scale="0.001 0.001 0.001"/>
      </geometry>
      <material name="abs_white"/>
    </visual>
    <collision>
      <origin rpy="0 0 0" xyz="0.025 0.0633 -0.244"/>
      <geometry>
        <mesh filename="../meshes/led_1.stl" scale="0.001 0.001 0.001"/>
      </geometry>
    </collision>
  </link>
  <link name="mount_1">
    <inertial>
      <origin rpy="0 0 0" xyz="-0.0015281452941265372 -0.027111778475479423 0.0047367407334450995"/>
      <mass value="0.03244923596791342"/>
      <inertia ixx="1.2e-05" ixy="0.0" ixz="-0.0" iyy="7e-06" iyz="-0.0" izz="6e-06"/>
    </inertial>
    <visual>
      <origin rpy="0 0 0" xyz="0.3074 0.0167 -0.273879"/>
      <geometry>
        <mesh filename="../meshes/mount_1.stl" scale="0.001 0.001 0.001"/>
      </geometry>
      <material name="abs_white"/>
    </visual>
    <collision>
      <origin rpy="0 0 0" xyz="0.3074 0.0167 -0.273879"/>
      <geometry>
        <mesh filename="../meshes/mount_1.stl" scale="0.001 0.001 0.001"/>
      </geometry>
    </collision>
  </link>
  <link name="led_axel_1">
    <inertial>
      <origin rpy="0 0 0" xyz="3.9681229292015674e-08 -0.017636071803263736 5.399675367945278e-08"/>
      <mass value="0.03211404074503917"/>
      <inertia ixx="1.9e-05" ixy="0.0" ixz="-0.0" iyy="0.0" iyz="-0.0" izz="1.9e-05"/>
    </inertial>
    <visual>
      <origin rpy="0 0 0" xyz="0.0175 0.0257 -0.274"/>
      <geometry>
        <mesh filename="../meshes/led_axel_1.stl" scale="0.001 0.001 0.001"/>
      </geometry>
      <material name="abs_white"/>
    </visual>
    <collision>
      <origin rpy="0 0 0" xyz="0.0175 0.0257 -0.274"/>
      <geometry>
        <mesh filename="../meshes/led_axel_1.stl" scale="0.001 0.001 0.001"/>
      </geometry>
    </collision>
  </link>
  <link name="lang_arm_1">
    <inertial>
      <origin rpy="0 0 0" xyz="-0.11940862738379322 -0.0002318340638047412 -0.003829064875622401"/>
      <mass value="0.16976147982888834"/>
      <inertia ixx="1.5e-05" ixy="-1.3e-05" ixz="-0.0" iyy="0.001196" iyz="-0.0" izz="0.001184"/>
    </inertial>
    <visual>
      <origin rpy="0 0 0" xyz="0.019 0.0127 -0.277708"/>
      <geometry>
        <mesh filename="../meshes/lang_arm_1.stl" scale="0.001 0.001 0.001"/>
      </geometry>
      <material name="abs_white"/>
    </visual>
    <collision>
      <origin rpy="0 0 0" xyz="0.019 0.0127 -0.277708"/>
      <geometry>
        <mesh filename="../meshes/lang_arm_1.stl" scale="0.001 0.001 0.001"/>
      </geometry>
    </collision>
  </link>
  <link name="lang_arm_Mirror__1">
    <inertial>
      <origin rpy="0 0 0" xyz="-0.11940862738379333 0.00023183404890350645 -0.003829064875622401"/>
      <mass value="0.1697614798288884"/>
      <inertia ixx="1.5e-05" ixy="1.3e-05" ixz="-0.0" iyy="0.001196" iyz="0.0" izz="0.001184"/>
    </inertial>
    <visual>
      <origin rpy="0 0 0" xyz="0.019 0.0727 -0.277708"/>
      <geometry>
        <mesh filename="../meshes/lang_arm_Mirror__1.stl" scale="0.001 0.001 0.001"/>
      </geometry>
      <material name="abs_white"/>
    </visual>
    <collision>
      <origin rpy="0 0 0" xyz="0.019 0.0727 -0.277708"/>
      <geometry>
        <mesh filename="../meshes/lang_arm_Mirror__1.stl" scale="0.001 0.001 0.001"/>
      </geometry>
    </collision>
  </link>
  <link name="ram_1">
    <inertial>
      <origin rpy="0 0 0" xyz="-0.019202424746526392 0.009473523246560166 -0.01755497164191755"/>
      <mass value="0.05700474756317414"/>
      <inertia ixx="1.9e-05" ixy="0.0" ixz="-2e-06" iyy="1.9e-05" iyz="-0.0" izz="3.1e-05"/>
    </inertial>
    <visual>
      <origin rpy="0 0 0" xyz="0.3114 0.0517 -0.283879"/>
      <geometry>
        <mesh filename="../meshes/ram_1.stl" scale="0.001 0.001 0.001"/>
      </geometry>
      <material name="abs_white"/>
    </visual>
    <collision>
      <origin rpy="0 0 0" xyz="0.3114 0.0517 -0.283879"/>
      <geometry>
        <mesh filename="../meshes/ram_1.stl" scale="0.001 0.001 0.001"/>
      </geometry>
    </collision>
  </link>
  <link name="Component18_1">
    <inertial>
      <origin rpy="0 0 0" xyz="-0.3064939998665962 -0.04140577938889977 0.25437893512310367"/>
      <mass value="0.009717848592679035"/>
      <inertia ixx="2e-06" ixy="-0.0" ixz="0.0" iyy="0.0" iyz="-0.0" izz="2e-06"/>
    </inertial>
    <visual>
      <origin rpy="0 0 0" xyz="0.029306 0.0026 -0.005"/>
      <geometry>
        <mesh filename="../meshes/Component18_1.stl" scale="0.001 0.001 0.001"/>
      </geometry>
      <material name="abs_white"/>
    </visual>
    <collision>
      <origin rpy="0 0 0" xyz="0.029306 0.0026 -0.005"/>
      <geometry>
        <mesh filename="../meshes/Component18_1.stl" scale="0.001 0.001 0.001"/>
      </geometry>
    </collision>
  </link>
  <link name="hake_1">
    <inertial>
      <origin rpy="0 0 0" xyz="-0.0026499780323618882 -0.007012922584167825 -0.026625758918819686"/>
      <mass value="0.008717252045640082"/>
      <inertia ixx="3e-06" ixy="-0.0" ixz="-0.0" iyy="4e-06" iyz="-0.0" izz="1e-06"/>
    </inertial>
    <visual>
      <origin rpy="0 0 0" xyz="0.3333 0.015006 -0.261879"/>
      <geometry>
        <mesh filename="../meshes/hake_1.stl" scale="0.001 0.001 0.001"/>
      </geometry>
      <material name="abs_white"/>
    </visual>
    <collision>
      <origin rpy="0 0 0" xyz="0.3333 0.015006 -0.261879"/>
      <geometry>
        <mesh filename="../meshes/hake_1.stl" scale="0.001 0.001 0.001"/>
      </geometry>
    </collision>
  </link>
  <link name="hake2_1">
    <inertial>
      <origin rpy="0 0 0" xyz="0.002649979198926289 0.0076133663675697905 -0.024953181253041634"/>
      <mass value="0.008505309594827988"/>
      <inertia ixx="3e-06" ixy="-0.0" ixz="0.0" iyy="3e-06" iyz="0.0" izz="1e-06"/>
    </inertial>
    <visual>
      <origin rpy="0 0 0" xyz="0.3383 0.073006 -0.261879"/>
      <geometry>
        <mesh filename="../meshes/hake2_1.stl" scale="0.001 0.001 0.001"/>
      </geometry>
      <material name="abs_white"/>
    </visual>
    <collision>
      <origin rpy="0 0 0" xyz="0.3383 0.073006 -0.261879"/>
      <geometry>
        <mesh filename="../meshes/hake2_1.stl" scale="0.001 0.001 0.001"/>
      </geometry>
    </collision>
  </link>
  <joint name="Slider 2" type="prismatic">
    <origin rpy="0 0 0" xyz="-0.01 -0.0005 -0.077"/>
    <parent link="base_link"/>
    <child link="glid_platta_1"/>
    <axis xyz="0.0 1.0 0.0"/>
    <limit effort="100" lower="0.0" upper="0.0" velocity="100"/>
  </joint>
  <joint name="Rigid 3" type="fixed">
    <origin rpy="0 0 0" xyz="-0.03 -0.095 0.016"/>
    <parent link="glid_platta_1"/>
    <child link="bas_1"/>
  </joint>
  <joint name="Rigid 4" type="fixed">
    <origin rpy="0 0 0" xyz="0.015 0.0895 0.0045"/>
    <parent link="bas_1"/>
    <child link="gemensam_vagg_1"/>
  </joint>
  <joint name="Revolute 5" type="continuous">
    <origin rpy="0 0 0" xyz="0.0075 -0.0023 0.0405"/>
    <parent link="gemensam_vagg_1"/>
    <child link="botten_snurr_1"/>
    <axis xyz="0.0 1.0 0.0"/>
  </joint>
  <joint name="Rigid 6" type="fixed">
    <origin rpy="0 0 0" xyz="-0.009 -0.009 0.015"/>
    <parent link="botten_snurr_1"/>
    <child link="kortarm_kopia_Mirror__1"/>
  </joint>
  <joint name="Rigid 7" type="fixed">
    <origin rpy="0 0 0" xyz="0.009 -0.059 0.015"/>
    <parent link="botten_snurr_1"/>
    <child link="kortarm_kopia_1"/>
  </joint>
  <joint name="Rigid 8" type="fixed">
    <origin rpy="0 0 0" xyz="0.03 0.0155 0.0045"/>
    <parent link="bas_1"/>
    <child link="snurr_hallare_stepper_sida_1"/>
  </joint>
  <joint name="Rigid 9" type="fixed">
    <origin rpy="0 0 0" xyz="-0.0165 0.004 0.245"/>
    <parent link="kortarm_kopia_1"/>
    <child link="led_1"/>
  </joint>
  <joint name="Revolute 12" type="continuous">
    <origin rpy="0 0 0" xyz="-0.2884 -0.004 -0.003829"/>
    <parent link="lang_arm_1"/>
    <child link="mount_1"/>
    <axis xyz="-0.0 -1.0 0.0"/>
  </joint>
  <joint name="Revolute 13" type="continuous">
    <origin rpy="0 0 0" xyz="0.0075 0.0376 0.03"/>
    <parent link="led_1"/>
    <child link="led_axel_1"/>
    <axis xyz="0.0 1.0 0.0"/>
  </joint>
  <joint name="Rigid 14" type="fixed">
    <origin rpy="0 0 0" xyz="-0.0015 0.013 0.003708"/>
    <parent link="led_axel_1"/>
    <child link="lang_arm_1"/>
  </joint>
  <joint name="Rigid 15" type="fixed">
    <origin rpy="0 0 0" xyz="-0.0015 -0.047 0.003708"/>
    <parent link="led_axel_1"/>
    <child link="lang_arm_Mirror__1"/>
  </joint>
  <joint name="Rigid 16" type="fixed">
    <origin rpy="0 0 0" xyz="-0.004 -0.035 0.01"/>
    <parent link="mount_1"/>
    <child link="ram_1"/>
  </joint>
  <joint name="Rigid 17" type="fixed">
    <origin rpy="0 0 0" xyz="0.282094 0.0491 -0.278879"/>
    <parent link="ram_1"/>
    <child link="Component18_1"/>
  </joint>
  <joint name="Slider 18" type="prismatic">
    <origin rpy="0 0 0" xyz="-0.303994 -0.012406 0.256879"/>
    <parent link="Component18_1"/>
    <child link="hake_1"/>
    <axis xyz="-0.0 1.0 0.0"/>
    <limit effort="100" lower="0.0" upper="0.0" velocity="100"/>
  </joint>
  <joint name="Slider 19" type="prismatic">
    <origin rpy="0 0 0" xyz="-0.308994 -0.070406 0.256879"/>
    <parent link="Component18_1"/>
    <child link="hake2_1"/>
    <axis xyz="0.0 -1.0 -0.0"/>
    <limit effort="100" lower="0.0" upper="0.0" velocity="100"/>
  </joint>
</robot>
